{
 "cells": [
  {
   "cell_type": "code",
   "execution_count": 9,
   "metadata": {},
   "outputs": [],
   "source": [
    "# Import Dependencies\n",
    "from flask import Flask, render_template, redirect\n",
    "#from flask_pymongo\n",
    "import pymongo\n",
    "import scrape_mars\n",
    "\n",
    "# Create Instance of Flask App\n",
    "#app = Flask(__name__)\n",
    "\n",
    "# Set up mongo connection in line \n",
    "#mongo = PyMongo(app, uri=\"mongodb://localhost:27017/mars_app\")\n",
    "conn = 'mongodb://localhost:27017/mars_app'\n",
    "\n",
    "client = pymongo.MongoClient(conn)\n",
    "\n",
    "\n",
    "\n",
    "\n",
    "\n",
    "#if __name__ == \"__main__\":\n",
    "#    app.run(debug=True)\n",
    "\n"
   ]
  },
  {
   "cell_type": "code",
   "execution_count": 10,
   "metadata": {},
   "outputs": [
    {
     "data": {
      "text/plain": [
       "Database(MongoClient(host=['localhost:27017'], document_class=dict, tz_aware=False, connect=True), 'mars_data')"
      ]
     },
     "execution_count": 10,
     "metadata": {},
     "output_type": "execute_result"
    }
   ],
   "source": [
    "client.mars_data"
   ]
  },
  {
   "cell_type": "code",
   "execution_count": 2,
   "metadata": {},
   "outputs": [],
   "source": [
    "def index():\n",
    "    # Finding one document from our mongoDB and return it\n",
    "    mars_data = mongo.db.mars_data.find_one()\n",
    "\n",
    "    # Pass that listing to render template\n",
    "    return render_template('index.html', mars_data=mars_data)\n",
    "\n",
    "\n",
    "#@app.route('/scrape')\n",
    "def scrape():\n",
    "    # Create mars info collection\n",
    "    mars = client.mars_data\n",
    "    mars_data = scrape_mars.scrape()\n",
    "    mars.update(\n",
    "        {},\n",
    "        mars_data,\n",
    "        upsert=True\n",
    "    )\n",
    "    return redirect(\"/\", code=302)\n"
   ]
  },
  {
   "cell_type": "code",
   "execution_count": 4,
   "metadata": {},
   "outputs": [
    {
     "ename": "TypeError",
     "evalue": "'Collection' object is not callable. If you meant to call the 'update' method on a 'Database' object it is failing because no such method exists.",
     "output_type": "error",
     "traceback": [
      "\u001b[1;31m---------------------------------------------------------------------------\u001b[0m",
      "\u001b[1;31mTypeError\u001b[0m                                 Traceback (most recent call last)",
      "\u001b[1;32m<ipython-input-4-20ef00fd5394>\u001b[0m in \u001b[0;36m<module>\u001b[1;34m\u001b[0m\n\u001b[1;32m----> 1\u001b[1;33m \u001b[0mscrape\u001b[0m\u001b[1;33m(\u001b[0m\u001b[1;33m)\u001b[0m\u001b[1;33m\u001b[0m\u001b[1;33m\u001b[0m\u001b[0m\n\u001b[0m",
      "\u001b[1;32m<ipython-input-2-70acec315c7b>\u001b[0m in \u001b[0;36mscrape\u001b[1;34m()\u001b[0m\n\u001b[0;32m     15\u001b[0m         \u001b[1;33m{\u001b[0m\u001b[1;33m}\u001b[0m\u001b[1;33m,\u001b[0m\u001b[1;33m\u001b[0m\u001b[1;33m\u001b[0m\u001b[0m\n\u001b[0;32m     16\u001b[0m         \u001b[0mmars_data\u001b[0m\u001b[1;33m,\u001b[0m\u001b[1;33m\u001b[0m\u001b[1;33m\u001b[0m\u001b[0m\n\u001b[1;32m---> 17\u001b[1;33m         \u001b[0mupsert\u001b[0m\u001b[1;33m=\u001b[0m\u001b[1;32mTrue\u001b[0m\u001b[1;33m\u001b[0m\u001b[1;33m\u001b[0m\u001b[0m\n\u001b[0m\u001b[0;32m     18\u001b[0m     )\n\u001b[0;32m     19\u001b[0m     \u001b[1;32mreturn\u001b[0m \u001b[0mredirect\u001b[0m\u001b[1;33m(\u001b[0m\u001b[1;34m\"/\"\u001b[0m\u001b[1;33m,\u001b[0m \u001b[0mcode\u001b[0m\u001b[1;33m=\u001b[0m\u001b[1;36m302\u001b[0m\u001b[1;33m)\u001b[0m\u001b[1;33m\u001b[0m\u001b[1;33m\u001b[0m\u001b[0m\n",
      "\u001b[1;32m~\\Anaconda3\\lib\\site-packages\\pymongo\\collection.py\u001b[0m in \u001b[0;36m__call__\u001b[1;34m(self, *args, **kwargs)\u001b[0m\n\u001b[0;32m   3337\u001b[0m                             \u001b[1;34m\"object it is failing because no such method \"\u001b[0m\u001b[1;33m\u001b[0m\u001b[1;33m\u001b[0m\u001b[0m\n\u001b[0;32m   3338\u001b[0m                             \u001b[1;34m\"exists.\"\u001b[0m \u001b[1;33m%\u001b[0m\u001b[1;33m\u001b[0m\u001b[1;33m\u001b[0m\u001b[0m\n\u001b[1;32m-> 3339\u001b[1;33m                             self.__name)\n\u001b[0m\u001b[0;32m   3340\u001b[0m         raise TypeError(\"'Collection' object is not callable. If you meant to \"\n\u001b[0;32m   3341\u001b[0m                         \u001b[1;34m\"call the '%s' method on a 'Collection' object it is \"\u001b[0m\u001b[1;33m\u001b[0m\u001b[1;33m\u001b[0m\u001b[0m\n",
      "\u001b[1;31mTypeError\u001b[0m: 'Collection' object is not callable. If you meant to call the 'update' method on a 'Database' object it is failing because no such method exists."
     ]
    }
   ],
   "source": [
    "scrape()"
   ]
  },
  {
   "cell_type": "code",
   "execution_count": 11,
   "metadata": {},
   "outputs": [],
   "source": [
    "mars = client.mars_data"
   ]
  },
  {
   "cell_type": "code",
   "execution_count": 6,
   "metadata": {},
   "outputs": [],
   "source": [
    "mars_data = scrape_mars.scrape()    "
   ]
  },
  {
   "cell_type": "code",
   "execution_count": 7,
   "metadata": {},
   "outputs": [
    {
     "ename": "TypeError",
     "evalue": "'Collection' object is not callable. If you meant to call the 'insert_one' method on a 'Database' object it is failing because no such method exists.",
     "output_type": "error",
     "traceback": [
      "\u001b[1;31m---------------------------------------------------------------------------\u001b[0m",
      "\u001b[1;31mTypeError\u001b[0m                                 Traceback (most recent call last)",
      "\u001b[1;32m<ipython-input-7-af0cd803b5e3>\u001b[0m in \u001b[0;36m<module>\u001b[1;34m\u001b[0m\n\u001b[0;32m      1\u001b[0m mars.insert_one(\n\u001b[0;32m      2\u001b[0m         \u001b[0mmars_data\u001b[0m\u001b[1;33m,\u001b[0m\u001b[1;33m\u001b[0m\u001b[1;33m\u001b[0m\u001b[0m\n\u001b[1;32m----> 3\u001b[1;33m         \u001b[0mupsert\u001b[0m\u001b[1;33m=\u001b[0m\u001b[1;32mTrue\u001b[0m\u001b[1;33m\u001b[0m\u001b[1;33m\u001b[0m\u001b[0m\n\u001b[0m\u001b[0;32m      4\u001b[0m     )\n",
      "\u001b[1;32m~\\Anaconda3\\lib\\site-packages\\pymongo\\collection.py\u001b[0m in \u001b[0;36m__call__\u001b[1;34m(self, *args, **kwargs)\u001b[0m\n\u001b[0;32m   3337\u001b[0m                             \u001b[1;34m\"object it is failing because no such method \"\u001b[0m\u001b[1;33m\u001b[0m\u001b[1;33m\u001b[0m\u001b[0m\n\u001b[0;32m   3338\u001b[0m                             \u001b[1;34m\"exists.\"\u001b[0m \u001b[1;33m%\u001b[0m\u001b[1;33m\u001b[0m\u001b[1;33m\u001b[0m\u001b[0m\n\u001b[1;32m-> 3339\u001b[1;33m                             self.__name)\n\u001b[0m\u001b[0;32m   3340\u001b[0m         raise TypeError(\"'Collection' object is not callable. If you meant to \"\n\u001b[0;32m   3341\u001b[0m                         \u001b[1;34m\"call the '%s' method on a 'Collection' object it is \"\u001b[0m\u001b[1;33m\u001b[0m\u001b[1;33m\u001b[0m\u001b[0m\n",
      "\u001b[1;31mTypeError\u001b[0m: 'Collection' object is not callable. If you meant to call the 'insert_one' method on a 'Database' object it is failing because no such method exists."
     ]
    }
   ],
   "source": [
    "mars.insert_one(\n",
    "        mars_data,\n",
    "        upsert=True\n",
    "    )"
   ]
  },
  {
   "cell_type": "code",
   "execution_count": 8,
   "metadata": {},
   "outputs": [
    {
     "ename": "TypeError",
     "evalue": "'Collection' object is not callable. If you meant to call the 'update_one' method on a 'Database' object it is failing because no such method exists.",
     "output_type": "error",
     "traceback": [
      "\u001b[1;31m---------------------------------------------------------------------------\u001b[0m",
      "\u001b[1;31mTypeError\u001b[0m                                 Traceback (most recent call last)",
      "\u001b[1;32m<ipython-input-8-e85d708a6ef8>\u001b[0m in \u001b[0;36m<module>\u001b[1;34m\u001b[0m\n\u001b[1;32m----> 1\u001b[1;33m \u001b[0mmars\u001b[0m\u001b[1;33m.\u001b[0m\u001b[0mupdate_one\u001b[0m\u001b[1;33m(\u001b[0m\u001b[1;33m{\u001b[0m\u001b[1;34m'name'\u001b[0m\u001b[1;33m:\u001b[0m \u001b[1;34m'mars'\u001b[0m\u001b[1;33m,\u001b[0m \u001b[1;34m\"news title\"\u001b[0m \u001b[1;33m:\u001b[0m \u001b[1;34m\"something here\"\u001b[0m\u001b[1;33m}\u001b[0m\u001b[1;33m)\u001b[0m\u001b[1;33m\u001b[0m\u001b[1;33m\u001b[0m\u001b[0m\n\u001b[0m",
      "\u001b[1;32m~\\Anaconda3\\lib\\site-packages\\pymongo\\collection.py\u001b[0m in \u001b[0;36m__call__\u001b[1;34m(self, *args, **kwargs)\u001b[0m\n\u001b[0;32m   3337\u001b[0m                             \u001b[1;34m\"object it is failing because no such method \"\u001b[0m\u001b[1;33m\u001b[0m\u001b[1;33m\u001b[0m\u001b[0m\n\u001b[0;32m   3338\u001b[0m                             \u001b[1;34m\"exists.\"\u001b[0m \u001b[1;33m%\u001b[0m\u001b[1;33m\u001b[0m\u001b[1;33m\u001b[0m\u001b[0m\n\u001b[1;32m-> 3339\u001b[1;33m                             self.__name)\n\u001b[0m\u001b[0;32m   3340\u001b[0m         raise TypeError(\"'Collection' object is not callable. If you meant to \"\n\u001b[0;32m   3341\u001b[0m                         \u001b[1;34m\"call the '%s' method on a 'Collection' object it is \"\u001b[0m\u001b[1;33m\u001b[0m\u001b[1;33m\u001b[0m\u001b[0m\n",
      "\u001b[1;31mTypeError\u001b[0m: 'Collection' object is not callable. If you meant to call the 'update_one' method on a 'Database' object it is failing because no such method exists."
     ]
    }
   ],
   "source": [
    "mars.update_one({'name': 'mars', \"news title\" : \"something here\"})"
   ]
  },
  {
   "cell_type": "code",
   "execution_count": null,
   "metadata": {},
   "outputs": [],
   "source": []
  }
 ],
 "metadata": {
  "kernelspec": {
   "display_name": "Python 3",
   "language": "python",
   "name": "python3"
  },
  "language_info": {
   "codemirror_mode": {
    "name": "ipython",
    "version": 3
   },
   "file_extension": ".py",
   "mimetype": "text/x-python",
   "name": "python",
   "nbconvert_exporter": "python",
   "pygments_lexer": "ipython3",
   "version": "3.7.3"
  }
 },
 "nbformat": 4,
 "nbformat_minor": 2
}
